2018-08-01 16:14:28,862 INFO:Microblog startup [in C:\Users\huanri\Documents\myproject\app\__init__.py:57]
2018-08-01 16:29:20,773 INFO:Microblog startup [in C:\Users\huanri\Documents\myproject\app\__init__.py:57]
2018-08-01 16:29:30,094 INFO:Microblog startup [in C:\Users\huanri\Documents\myproject\app\__init__.py:57]
2018-08-01 16:29:40,146 INFO:Microblog startup [in C:\Users\huanri\Documents\myproject\app\__init__.py:57]
2018-08-01 16:30:48,969 INFO:Microblog startup [in C:\Users\huanri\Documents\myproject\app\__init__.py:57]
2018-08-01 16:32:57,527 ERROR:Exception on /user/mimi [GET] [in c:\python36\lib\site-packages\flask\app.py:1761]
Traceback (most recent call last):
  File "c:\python36\lib\site-packages\flask\app.py", line 2292, in wsgi_app
    response = self.full_dispatch_request()
  File "c:\python36\lib\site-packages\flask\app.py", line 1815, in full_dispatch_request
    rv = self.handle_user_exception(e)
  File "c:\python36\lib\site-packages\flask\app.py", line 1718, in handle_user_exception
    reraise(exc_type, exc_value, tb)
  File "c:\python36\lib\site-packages\flask\_compat.py", line 35, in reraise
    raise value
  File "c:\python36\lib\site-packages\flask\app.py", line 1811, in full_dispatch_request
    rv = self.preprocess_request()
  File "c:\python36\lib\site-packages\flask\app.py", line 2087, in preprocess_request
    rv = func()
  File "C:\Users\huanri\Documents\myproject\app\views.py", line 30, in before_request
    if current_user.is_authenticated:
  File "c:\python36\lib\site-packages\werkzeug\local.py", line 347, in __getattr__
    return getattr(self._get_current_object(), name)
  File "c:\python36\lib\site-packages\werkzeug\local.py", line 306, in _get_current_object
    return self.__local()
  File "c:\python36\lib\site-packages\flask_login\utils.py", line 26, in <lambda>
    current_user = LocalProxy(lambda: _get_user())
  File "c:\python36\lib\site-packages\flask_login\utils.py", line 335, in _get_user
    current_app.login_manager._load_user()
  File "c:\python36\lib\site-packages\flask_login\login_manager.py", line 359, in _load_user
    return self.reload_user()
  File "c:\python36\lib\site-packages\flask_login\login_manager.py", line 321, in reload_user
    user = self.user_callback(user_id)
  File "C:\Users\huanri\Documents\myproject\app\models.py", line 85, in load_user
    return User.query.get(int(id))
  File "c:\python36\lib\site-packages\flask_sqlalchemy\__init__.py", line 512, in __get__
    mapper = orm.class_mapper(type)
  File "c:\python36\lib\site-packages\sqlalchemy\orm\base.py", line 421, in class_mapper
    mapper = _inspect_mapped_class(class_, configure=configure)
  File "c:\python36\lib\site-packages\sqlalchemy\orm\base.py", line 400, in _inspect_mapped_class
    mapper._configure_all()
  File "c:\python36\lib\site-packages\sqlalchemy\orm\mapper.py", line 1272, in _configure_all
    configure_mappers()
  File "c:\python36\lib\site-packages\sqlalchemy\orm\mapper.py", line 3029, in configure_mappers
    mapper._post_configure_properties()
  File "c:\python36\lib\site-packages\sqlalchemy\orm\mapper.py", line 1828, in _post_configure_properties
    prop.init()
  File "c:\python36\lib\site-packages\sqlalchemy\orm\interfaces.py", line 183, in init
    self.do_init()
  File "c:\python36\lib\site-packages\sqlalchemy\orm\relationships.py", line 1659, in do_init
    self._generate_backref()
  File "c:\python36\lib\site-packages\sqlalchemy\orm\relationships.py", line 1849, in _generate_backref
    (backref_key, self, m))
sqlalchemy.exc.ArgumentError: Error creating backref 'followers' on relationship 'User.followers': property of that name exists on mapper 'Mapper|User|user'
2018-08-01 16:33:00,124 ERROR:Exception on /user/mimi [GET] [in c:\python36\lib\site-packages\flask\app.py:1761]
Traceback (most recent call last):
  File "c:\python36\lib\site-packages\flask\app.py", line 2292, in wsgi_app
    response = self.full_dispatch_request()
  File "c:\python36\lib\site-packages\flask\app.py", line 1815, in full_dispatch_request
    rv = self.handle_user_exception(e)
  File "c:\python36\lib\site-packages\flask\app.py", line 1718, in handle_user_exception
    reraise(exc_type, exc_value, tb)
  File "c:\python36\lib\site-packages\flask\_compat.py", line 35, in reraise
    raise value
  File "c:\python36\lib\site-packages\flask\app.py", line 1811, in full_dispatch_request
    rv = self.preprocess_request()
  File "c:\python36\lib\site-packages\flask\app.py", line 2087, in preprocess_request
    rv = func()
  File "C:\Users\huanri\Documents\myproject\app\views.py", line 30, in before_request
    if current_user.is_authenticated:
  File "c:\python36\lib\site-packages\werkzeug\local.py", line 347, in __getattr__
    return getattr(self._get_current_object(), name)
  File "c:\python36\lib\site-packages\werkzeug\local.py", line 306, in _get_current_object
    return self.__local()
  File "c:\python36\lib\site-packages\flask_login\utils.py", line 26, in <lambda>
    current_user = LocalProxy(lambda: _get_user())
  File "c:\python36\lib\site-packages\flask_login\utils.py", line 335, in _get_user
    current_app.login_manager._load_user()
  File "c:\python36\lib\site-packages\flask_login\login_manager.py", line 359, in _load_user
    return self.reload_user()
  File "c:\python36\lib\site-packages\flask_login\login_manager.py", line 321, in reload_user
    user = self.user_callback(user_id)
  File "C:\Users\huanri\Documents\myproject\app\models.py", line 85, in load_user
    return User.query.get(int(id))
  File "c:\python36\lib\site-packages\flask_sqlalchemy\__init__.py", line 512, in __get__
    mapper = orm.class_mapper(type)
  File "c:\python36\lib\site-packages\sqlalchemy\orm\base.py", line 421, in class_mapper
    mapper = _inspect_mapped_class(class_, configure=configure)
  File "c:\python36\lib\site-packages\sqlalchemy\orm\base.py", line 400, in _inspect_mapped_class
    mapper._configure_all()
  File "c:\python36\lib\site-packages\sqlalchemy\orm\mapper.py", line 1272, in _configure_all
    configure_mappers()
  File "c:\python36\lib\site-packages\sqlalchemy\orm\mapper.py", line 3026, in configure_mappers
    raise e
sqlalchemy.exc.InvalidRequestError: One or more mappers failed to initialize - can't proceed with initialization of other mappers. Triggering mapper: 'Mapper|User|user'. Original exception was: Error creating backref 'followers' on relationship 'User.followers': property of that name exists on mapper 'Mapper|User|user'
2018-08-01 16:48:47,911 INFO:Microblog startup [in C:\Users\huanri\Documents\myproject\app\__init__.py:57]
2018-08-01 16:48:56,980 INFO:Microblog startup [in C:\Users\huanri\Documents\myproject\app\__init__.py:57]
2018-08-01 16:49:11,372 INFO:Microblog startup [in C:\Users\huanri\Documents\myproject\app\__init__.py:57]
2018-08-01 16:49:17,428 INFO:Microblog startup [in C:\Users\huanri\Documents\myproject\app\__init__.py:57]
2018-08-01 16:49:29,134 INFO:Microblog startup [in C:\Users\huanri\Documents\myproject\app\__init__.py:57]
2018-08-01 18:09:48,068 INFO:Microblog startup [in C:\Users\huanri\Documents\myproject\app\__init__.py:57]
2018-08-01 23:06:20,012 INFO:Microblog startup [in C:\Users\huanri\Documents\myproject\app\__init__.py:57]
2018-08-01 23:14:01,846 INFO:Microblog startup [in C:\Users\huanri\Documents\myproject\app\__init__.py:57]
2018-08-01 23:14:36,641 INFO:Microblog startup [in C:\Users\huanri\Documents\myproject\app\__init__.py:57]
