2018-07-30 16:44:24,243 ERROR:Exception on /edit_profile [POST] [in c:\python36\lib\site-packages\flask\app.py:1761]
Traceback (most recent call last):
  File "c:\python36\lib\site-packages\flask\app.py", line 2292, in wsgi_app
    response = self.full_dispatch_request()
  File "c:\python36\lib\site-packages\flask\app.py", line 1815, in full_dispatch_request
    rv = self.handle_user_exception(e)
  File "c:\python36\lib\site-packages\flask\app.py", line 1718, in handle_user_exception
    reraise(exc_type, exc_value, tb)
  File "c:\python36\lib\site-packages\flask\_compat.py", line 35, in reraise
    raise value
  File "c:\python36\lib\site-packages\flask\app.py", line 1813, in full_dispatch_request
    rv = self.dispatch_request()
  File "c:\python36\lib\site-packages\flask\app.py", line 1799, in dispatch_request
    return self.view_functions[rule.endpoint](**req.view_args)
  File "c:\python36\lib\site-packages\flask_login\utils.py", line 261, in decorated_view
    return func(*args, **kwargs)
  File "C:\Users\huanri\Documents\myproject\app\views.py", line 59, in edit_profile
    if form.validate_on_submit():
  File "c:\python36\lib\site-packages\flask_wtf\form.py", line 101, in validate_on_submit
    return self.is_submitted() and self.validate()
  File "c:\python36\lib\site-packages\wtforms\form.py", line 310, in validate
    return super(Form, self).validate(extra)
  File "c:\python36\lib\site-packages\wtforms\form.py", line 152, in validate
    if not field.validate(self, extra):
  File "c:\python36\lib\site-packages\wtforms\fields\core.py", line 206, in validate
    stop_validation = self._run_validation_chain(form, chain)
  File "c:\python36\lib\site-packages\wtforms\fields\core.py", line 226, in _run_validation_chain
    validator(form, self)
  File "C:\Users\huanri\Documents\myproject\app\form.py", line 49, in validate_username
NameError: name 'ValidationError' is not defined
2018-07-30 16:52:06,491 ERROR:Exception on /edit_profile [POST] [in c:\python36\lib\site-packages\flask\app.py:1761]
Traceback (most recent call last):
  File "c:\python36\lib\site-packages\flask\app.py", line 2292, in wsgi_app
    response = self.full_dispatch_request()
  File "c:\python36\lib\site-packages\flask\app.py", line 1815, in full_dispatch_request
    rv = self.handle_user_exception(e)
  File "c:\python36\lib\site-packages\flask\app.py", line 1718, in handle_user_exception
    reraise(exc_type, exc_value, tb)
  File "c:\python36\lib\site-packages\flask\_compat.py", line 35, in reraise
    raise value
  File "c:\python36\lib\site-packages\flask\app.py", line 1813, in full_dispatch_request
    rv = self.dispatch_request()
  File "c:\python36\lib\site-packages\flask\app.py", line 1799, in dispatch_request
    return self.view_functions[rule.endpoint](**req.view_args)
  File "c:\python36\lib\site-packages\flask_login\utils.py", line 261, in decorated_view
    return func(*args, **kwargs)
  File "C:\Users\huanri\Documents\myproject\app\views.py", line 59, in edit_profile
    if form.validate_on_submit():
  File "c:\python36\lib\site-packages\flask_wtf\form.py", line 101, in validate_on_submit
    return self.is_submitted() and self.validate()
  File "c:\python36\lib\site-packages\wtforms\form.py", line 310, in validate
    return super(Form, self).validate(extra)
  File "c:\python36\lib\site-packages\wtforms\form.py", line 152, in validate
    if not field.validate(self, extra):
  File "c:\python36\lib\site-packages\wtforms\fields\core.py", line 206, in validate
    stop_validation = self._run_validation_chain(form, chain)
  File "c:\python36\lib\site-packages\wtforms\fields\core.py", line 226, in _run_validation_chain
    validator(form, self)
  File "C:\Users\huanri\Documents\myproject\app\form.py", line 49, in validate_username
NameError: name 'ValidationError' is not defined
2018-07-30 16:56:06,270 INFO:Microblog startup [in C:\Users\huanri\Documents\myproject\app\__init__.py:59]
2018-07-30 17:01:59,913 INFO:Microblog startup [in C:\Users\huanri\Documents\myproject\app\__init__.py:59]
2018-07-30 17:02:28,577 INFO:Microblog startup [in C:\Users\huanri\Documents\myproject\app\__init__.py:59]
2018-07-30 17:02:40,314 ERROR:Exception on /edit_profile [POST] [in c:\python36\lib\site-packages\flask\app.py:1761]
Traceback (most recent call last):
  File "c:\python36\lib\site-packages\flask\app.py", line 2292, in wsgi_app
    response = self.full_dispatch_request()
  File "c:\python36\lib\site-packages\flask\app.py", line 1815, in full_dispatch_request
    rv = self.handle_user_exception(e)
  File "c:\python36\lib\site-packages\flask\app.py", line 1718, in handle_user_exception
    reraise(exc_type, exc_value, tb)
  File "c:\python36\lib\site-packages\flask\_compat.py", line 35, in reraise
    raise value
  File "c:\python36\lib\site-packages\flask\app.py", line 1813, in full_dispatch_request
    rv = self.dispatch_request()
  File "c:\python36\lib\site-packages\flask\app.py", line 1799, in dispatch_request
    return self.view_functions[rule.endpoint](**req.view_args)
  File "c:\python36\lib\site-packages\flask_login\utils.py", line 261, in decorated_view
    return func(*args, **kwargs)
  File "C:\Users\huanri\Documents\myproject\app\views.py", line 59, in edit_profile
    if form.validate_on_submit():
  File "c:\python36\lib\site-packages\flask_wtf\form.py", line 101, in validate_on_submit
    return self.is_submitted() and self.validate()
  File "c:\python36\lib\site-packages\wtforms\form.py", line 310, in validate
    return super(Form, self).validate(extra)
  File "c:\python36\lib\site-packages\wtforms\form.py", line 152, in validate
    if not field.validate(self, extra):
  File "c:\python36\lib\site-packages\wtforms\fields\core.py", line 206, in validate
    stop_validation = self._run_validation_chain(form, chain)
  File "c:\python36\lib\site-packages\wtforms\fields\core.py", line 226, in _run_validation_chain
    validator(form, self)
  File "C:\Users\huanri\Documents\myproject\app\form.py", line 58, in validate_username
    raise ValidationErrorrsfs('Please use a different username.')
NameError: name 'ValidationErrorrsfs' is not defined
2018-07-30 17:03:03,285 ERROR:Exception on /edit_profile [POST] [in c:\python36\lib\site-packages\flask\app.py:1761]
Traceback (most recent call last):
  File "c:\python36\lib\site-packages\flask\app.py", line 2292, in wsgi_app
    response = self.full_dispatch_request()
  File "c:\python36\lib\site-packages\flask\app.py", line 1815, in full_dispatch_request
    rv = self.handle_user_exception(e)
  File "c:\python36\lib\site-packages\flask\app.py", line 1718, in handle_user_exception
    reraise(exc_type, exc_value, tb)
  File "c:\python36\lib\site-packages\flask\_compat.py", line 35, in reraise
    raise value
  File "c:\python36\lib\site-packages\flask\app.py", line 1813, in full_dispatch_request
    rv = self.dispatch_request()
  File "c:\python36\lib\site-packages\flask\app.py", line 1799, in dispatch_request
    return self.view_functions[rule.endpoint](**req.view_args)
  File "c:\python36\lib\site-packages\flask_login\utils.py", line 261, in decorated_view
    return func(*args, **kwargs)
  File "C:\Users\huanri\Documents\myproject\app\views.py", line 59, in edit_profile
    if form.validate_on_submit():
  File "c:\python36\lib\site-packages\flask_wtf\form.py", line 101, in validate_on_submit
    return self.is_submitted() and self.validate()
  File "c:\python36\lib\site-packages\wtforms\form.py", line 310, in validate
    return super(Form, self).validate(extra)
  File "c:\python36\lib\site-packages\wtforms\form.py", line 152, in validate
    if not field.validate(self, extra):
  File "c:\python36\lib\site-packages\wtforms\fields\core.py", line 206, in validate
    stop_validation = self._run_validation_chain(form, chain)
  File "c:\python36\lib\site-packages\wtforms\fields\core.py", line 226, in _run_validation_chain
    validator(form, self)
  File "C:\Users\huanri\Documents\myproject\app\form.py", line 58, in validate_username
    raise ValidationError('Please use a different username.')
NameError: name 'ValidationErrorrsfs' is not defined
2018-07-30 17:03:12,885 INFO:Microblog startup [in C:\Users\huanri\Documents\myproject\app\__init__.py:59]
2018-07-30 17:07:39,799 INFO:Microblog startup [in C:\Users\huanri\Documents\myproject\app\__init__.py:59]
2018-07-30 18:21:06,809 INFO:Microblog startup [in C:\Users\huanri\Documents\myproject\app\__init__.py:59]
2018-07-30 18:21:51,398 INFO:Microblog startup [in C:\Users\huanri\Documents\myproject\app\__init__.py:59]
2018-07-30 18:22:15,756 INFO:Microblog startup [in C:\Users\huanri\Documents\myproject\app\__init__.py:59]
2018-07-30 20:15:07,551 INFO:Microblog startup [in C:\Users\huanri\Documents\myproject\app\__init__.py:59]
2018-07-30 20:15:35,038 INFO:Microblog startup [in C:\Users\huanri\Documents\myproject\app\__init__.py:59]
2018-07-31 00:17:14,230 INFO:Microblog startup [in C:\Users\huanri\Documents\myproject\app\__init__.py:57]
2018-07-31 00:18:07,752 INFO:Microblog startup [in C:\Users\huanri\Documents\myproject\app\__init__.py:57]
2018-07-31 00:21:36,266 INFO:Microblog startup [in C:\Users\huanri\Documents\myproject\app\__init__.py:57]
2018-07-31 00:21:49,513 INFO:Microblog startup [in C:\Users\huanri\Documents\myproject\app\__init__.py:57]
2018-07-31 00:22:01,220 INFO:Microblog startup [in C:\Users\huanri\Documents\myproject\app\__init__.py:57]
2018-07-31 00:22:17,114 INFO:Microblog startup [in C:\Users\huanri\Documents\myproject\app\__init__.py:57]
2018-07-31 00:23:28,856 INFO:Microblog startup [in C:\Users\huanri\Documents\myproject\app\__init__.py:57]
2018-07-31 00:23:49,041 INFO:Microblog startup [in C:\Users\huanri\Documents\myproject\app\__init__.py:57]
2018-07-31 01:10:33,416 INFO:Microblog startup [in C:\Users\huanri\Documents\myproject\app\__init__.py:57]
